<mujoco model="eel_2d_stl_rebuild">
  <compiler angle="degree" autolimits="true" inertiafromgeom="true" meshdir="generated_stl"/>
  <option timestep="0.002" gravity="0 0 0" integrator="implicitfast" cone="elliptic" iterations="100">
    <flag contact="disable"/>
  </option>
  <default>
    <site type="sphere" size="0.004" rgba="0.90 0.20 0.20 1" group="3"/>
    <default class="root_joint">
      <joint limited="false" stiffness="0" armature="0.01" damping="0.4"/>
    </default>
    <default class="active_hinge">
      <joint type="hinge" axis="0 0 1" limited="true" range="-15 15" stiffness="1.041" damping="0.05" armature="0.0005"/>
    </default>
    <default class="tail_hinge">
      <joint type="hinge" axis="0 0 1" limited="true" range="-25 25" stiffness="0.18" damping="0.02" armature="0.0002"/>
    </default>
    <default class="tendon_motor">
      <motor ctrllimited="true" ctrlrange="0 100" gear="1"/>
    </default>
  </default>
<asset>
  <mesh name="centre_compartment_mesh" file="centre_compartment_mesh.stl"/>
  <mesh name="vertebra_mesh" file="vertebra_mesh.stl"/>
  <mesh name="head_mesh" file="head_mesh.stl"/>
  <mesh name="tail_joint_mesh" file="tail_joint_mesh.stl"/>
  <mesh name="tail_seg1_mesh" file="tail_seg1_mesh.stl"/>
  <mesh name="tail_seg2_mesh" file="tail_seg2_mesh.stl"/>
  <mesh name="tail_seg3_mesh" file="tail_seg3_mesh.stl"/>
  <mesh name="tail_seg4_mesh" file="tail_seg4_mesh.stl"/>
</asset>
  <worldbody>
    <light name="light" directional="true" diffuse="0.8 0.8 0.8" pos="0 0 2.5"/>
    <camera name="top" pos="0 0 2.2" xyaxes="1 0 0 0 1 0"/>
    <camera name="oblique" pos="-1.2 -1.6 0.9" xyaxes="0.8 -0.6 0 0.2 0.3 0.93"/>
    <body name="centre_compartment" pos="0 0 0">
      <joint name="root_x" class="root_joint" type="slide" axis="1 0 0"/>
      <joint name="root_y" class="root_joint" type="slide" axis="0 1 0"/>
      <joint name="root_yaw" class="root_joint" type="hinge" axis="0 0 1"/>
      <geom name="centre_compartment_dyn" type="box" size="0.175 0.06 0.06" density="190" rgba="0 0 0 0" contype="0" conaffinity="0" group="4"/>
      <geom name="centre_compartment_vis" type="mesh" mesh="centre_compartment_mesh" mass="0" rgba="0.18 0.22 0.33 1" contype="0" conaffinity="0" group="1"/>
      <site name="centre_reference" pos="0 0 0" rgba="0 0 0 0"/>
      <site name="centre_front_left" pos="0.175 0.0375 0"/>
      <site name="centre_front_right" pos="0.175 -0.0375 0"/>
      <site name="centre_back_left" pos="-0.175 0.0375 0"/>
      <site name="centre_back_right" pos="-0.175 -0.0375 0"/>
      <body name="front_v1" pos="0.229 0 0">
        <joint name="front_v1_yaw" class="active_hinge"/>
        <geom name="front_v1_dyn" type="box" size="0.004 0.044985 0.045" density="220" rgba="0 0 0 0" contype="0" conaffinity="0" group="4"/>
        <geom name="front_v1_vis" type="mesh" mesh="vertebra_mesh" mass="0" rgba="0.20 0.54 0.81 1" contype="0" conaffinity="0" group="1"/>
        <site name="front_v1_left" pos="0 0.0375 0"/>
        <site name="front_v1_right" pos="0 -0.0375 0"/>
        <body name="front_v2" pos="0.05 0 0">
          <joint name="front_v2_yaw" class="active_hinge"/>
          <geom name="front_v2_dyn" type="box" size="0.004 0.044985 0.045" density="220" rgba="0 0 0 0" contype="0" conaffinity="0" group="4"/>
          <geom name="front_v2_vis" type="mesh" mesh="vertebra_mesh" mass="0" rgba="0.20 0.54 0.81 1" contype="0" conaffinity="0" group="1"/>
          <site name="front_v2_left" pos="0 0.0375 0"/>
          <site name="front_v2_right" pos="0 -0.0375 0"/>
          <body name="front_v3" pos="0.05 0 0">
            <joint name="front_v3_yaw" class="active_hinge"/>
            <geom name="front_v3_dyn" type="box" size="0.004 0.044985 0.045" density="220" rgba="0 0 0 0" contype="0" conaffinity="0" group="4"/>
            <geom name="front_v3_vis" type="mesh" mesh="vertebra_mesh" mass="0" rgba="0.20 0.54 0.81 1" contype="0" conaffinity="0" group="1"/>
            <site name="front_v3_left" pos="0 0.0375 0"/>
            <site name="front_v3_right" pos="0 -0.0375 0"/>
            <body name="front_v4" pos="0.05 0 0">
              <joint name="front_v4_yaw" class="active_hinge"/>
              <geom name="front_v4_dyn" type="box" size="0.004 0.044985 0.045" density="220" rgba="0 0 0 0" contype="0" conaffinity="0" group="4"/>
              <geom name="front_v4_vis" type="mesh" mesh="vertebra_mesh" mass="0" rgba="0.20 0.54 0.81 1" contype="0" conaffinity="0" group="1"/>
              <site name="front_v4_left" pos="0 0.0375 0"/>
              <site name="front_v4_right" pos="0 -0.0375 0"/>
              <body name="front_v5" pos="0.05 0 0">
                <joint name="front_v5_yaw" class="active_hinge"/>
                <geom name="front_v5_dyn" type="box" size="0.004 0.044985 0.045" density="220" rgba="0 0 0 0" contype="0" conaffinity="0" group="4"/>
                <geom name="front_v5_vis" type="mesh" mesh="vertebra_mesh" mass="0" rgba="0.20 0.54 0.81 1" contype="0" conaffinity="0" group="1"/>
                <site name="front_v5_left" pos="0 0.0375 0"/>
                <site name="front_v5_right" pos="0 -0.0375 0"/>
                <body name="front_v6" pos="0.05 0 0">
                  <joint name="front_v6_yaw" class="active_hinge"/>
                  <geom name="front_v6_dyn" type="box" size="0.004 0.044985 0.045" density="220" rgba="0 0 0 0" contype="0" conaffinity="0" group="4"/>
                  <geom name="front_v6_vis" type="mesh" mesh="vertebra_mesh" mass="0" rgba="0.20 0.54 0.81 1" contype="0" conaffinity="0" group="1"/>
                  <site name="front_v6_left" pos="0 0.0375 0"/>
                  <site name="front_v6_right" pos="0 -0.0375 0"/>
                  <body name="front_v7" pos="0.05 0 0">
                    <joint name="front_v7_yaw" class="active_hinge"/>
                    <geom name="front_v7_dyn" type="box" size="0.004 0.044985 0.045" density="220" rgba="0 0 0 0" contype="0" conaffinity="0" group="4"/>
                    <geom name="front_v7_vis" type="mesh" mesh="vertebra_mesh" mass="0" rgba="0.20 0.54 0.81 1" contype="0" conaffinity="0" group="1"/>
                    <site name="front_v7_left" pos="0 0.0375 0"/>
                    <site name="front_v7_right" pos="0 -0.0375 0"/>
                    <body name="front_v8" pos="0.05 0 0">
                      <joint name="front_v8_yaw" class="active_hinge"/>
                      <geom name="front_v8_dyn" type="box" size="0.004 0.044985 0.045" density="220" rgba="0 0 0 0" contype="0" conaffinity="0" group="4"/>
                      <geom name="front_v8_vis" type="mesh" mesh="vertebra_mesh" mass="0" rgba="0.20 0.54 0.81 1" contype="0" conaffinity="0" group="1"/>
                      <site name="front_v8_left" pos="0 0.0375 0"/>
                      <site name="front_v8_right" pos="0 -0.0375 0"/>
                      <body name="front_v9" pos="0.05 0 0">
                        <joint name="front_v9_yaw" class="active_hinge"/>
                        <geom name="front_v9_dyn" type="box" size="0.004 0.044985 0.045" density="220" rgba="0 0 0 0" contype="0" conaffinity="0" group="4"/>
                        <geom name="front_v9_vis" type="mesh" mesh="vertebra_mesh" mass="0" rgba="0.20 0.54 0.81 1" contype="0" conaffinity="0" group="1"/>
                        <site name="front_v9_left" pos="0 0.0375 0"/>
                        <site name="front_v9_right" pos="0 -0.0375 0"/>
                        <body name="head" pos="0.1315 0 0">
                          <joint name="head_yaw" class="active_hinge"/>
                          <geom name="head_dyn" type="box" size="0.0775 0.044989 0.044989" density="220" rgba="0 0 0 0" contype="0" conaffinity="0" group="4"/>
                          <geom name="head_vis" type="mesh" mesh="head_mesh" mass="0" rgba="0.10 0.37 0.64 1" contype="0" conaffinity="0" group="1"/>
                          <site name="head_left" pos="-0.0725 0.0375 0"/>
                          <site name="head_right" pos="-0.0725 -0.0375 0"/>
                        </body>
                      </body>
                    </body>
                  </body>
                </body>
              </body>
            </body>
          </body>
        </body>
      </body>
      <body name="back_v1" pos="-0.229 0 0">
        <joint name="back_v1_yaw" class="active_hinge"/>
        <geom name="back_v1_dyn" type="box" size="0.004 0.044985 0.045" density="220" rgba="0 0 0 0" contype="0" conaffinity="0" group="4"/>
        <geom name="back_v1_vis" type="mesh" mesh="vertebra_mesh" mass="0" rgba="0.20 0.54 0.81 1" contype="0" conaffinity="0" group="1"/>
        <site name="back_v1_left" pos="0 0.0375 0"/>
        <site name="back_v1_right" pos="0 -0.0375 0"/>
        <body name="back_v2" pos="-0.05 0 0">
          <joint name="back_v2_yaw" class="active_hinge"/>
          <geom name="back_v2_dyn" type="box" size="0.004 0.044985 0.045" density="220" rgba="0 0 0 0" contype="0" conaffinity="0" group="4"/>
          <geom name="back_v2_vis" type="mesh" mesh="vertebra_mesh" mass="0" rgba="0.20 0.54 0.81 1" contype="0" conaffinity="0" group="1"/>
          <site name="back_v2_left" pos="0 0.0375 0"/>
          <site name="back_v2_right" pos="0 -0.0375 0"/>
          <body name="back_v3" pos="-0.05 0 0">
            <joint name="back_v3_yaw" class="active_hinge"/>
            <geom name="back_v3_dyn" type="box" size="0.004 0.044985 0.045" density="220" rgba="0 0 0 0" contype="0" conaffinity="0" group="4"/>
            <geom name="back_v3_vis" type="mesh" mesh="vertebra_mesh" mass="0" rgba="0.20 0.54 0.81 1" contype="0" conaffinity="0" group="1"/>
            <site name="back_v3_left" pos="0 0.0375 0"/>
            <site name="back_v3_right" pos="0 -0.0375 0"/>
            <body name="back_v4" pos="-0.05 0 0">
              <joint name="back_v4_yaw" class="active_hinge"/>
              <geom name="back_v4_dyn" type="box" size="0.004 0.044985 0.045" density="220" rgba="0 0 0 0" contype="0" conaffinity="0" group="4"/>
              <geom name="back_v4_vis" type="mesh" mesh="vertebra_mesh" mass="0" rgba="0.20 0.54 0.81 1" contype="0" conaffinity="0" group="1"/>
              <site name="back_v4_left" pos="0 0.0375 0"/>
              <site name="back_v4_right" pos="0 -0.0375 0"/>
              <body name="back_v5" pos="-0.05 0 0">
                <joint name="back_v5_yaw" class="active_hinge"/>
                <geom name="back_v5_dyn" type="box" size="0.004 0.044985 0.045" density="220" rgba="0 0 0 0" contype="0" conaffinity="0" group="4"/>
                <geom name="back_v5_vis" type="mesh" mesh="vertebra_mesh" mass="0" rgba="0.20 0.54 0.81 1" contype="0" conaffinity="0" group="1"/>
                <site name="back_v5_left" pos="0 0.0375 0"/>
                <site name="back_v5_right" pos="0 -0.0375 0"/>
                <body name="back_v6" pos="-0.05 0 0">
                  <joint name="back_v6_yaw" class="active_hinge"/>
                  <geom name="back_v6_dyn" type="box" size="0.004 0.044985 0.045" density="220" rgba="0 0 0 0" contype="0" conaffinity="0" group="4"/>
                  <geom name="back_v6_vis" type="mesh" mesh="vertebra_mesh" mass="0" rgba="0.20 0.54 0.81 1" contype="0" conaffinity="0" group="1"/>
                  <site name="back_v6_left" pos="0 0.0375 0"/>
                  <site name="back_v6_right" pos="0 -0.0375 0"/>
                  <body name="back_v7" pos="-0.05 0 0">
                    <joint name="back_v7_yaw" class="active_hinge"/>
                    <geom name="back_v7_dyn" type="box" size="0.004 0.044985 0.045" density="220" rgba="0 0 0 0" contype="0" conaffinity="0" group="4"/>
                    <geom name="back_v7_vis" type="mesh" mesh="vertebra_mesh" mass="0" rgba="0.20 0.54 0.81 1" contype="0" conaffinity="0" group="1"/>
                    <site name="back_v7_left" pos="0 0.0375 0"/>
                    <site name="back_v7_right" pos="0 -0.0375 0"/>
                    <body name="back_v8" pos="-0.05 0 0">
                      <joint name="back_v8_yaw" class="active_hinge"/>
                      <geom name="back_v8_dyn" type="box" size="0.004 0.044985 0.045" density="220" rgba="0 0 0 0" contype="0" conaffinity="0" group="4"/>
                      <geom name="back_v8_vis" type="mesh" mesh="vertebra_mesh" mass="0" rgba="0.20 0.54 0.81 1" contype="0" conaffinity="0" group="1"/>
                      <site name="back_v8_left" pos="0 0.0375 0"/>
                      <site name="back_v8_right" pos="0 -0.0375 0"/>
                      <body name="back_v9" pos="-0.05 0 0">
                        <joint name="back_v9_yaw" class="active_hinge"/>
                        <geom name="back_v9_dyn" type="box" size="0.004 0.044985 0.045" density="220" rgba="0 0 0 0" contype="0" conaffinity="0" group="4"/>
                        <geom name="back_v9_vis" type="mesh" mesh="vertebra_mesh" mass="0" rgba="0.20 0.54 0.81 1" contype="0" conaffinity="0" group="1"/>
                        <site name="back_v9_left" pos="0 0.0375 0"/>
                        <site name="back_v9_right" pos="0 -0.0375 0"/>
                        <body name="joint_tail" pos="-0.109 0 0">
                          <joint name="joint_tail_yaw" class="active_hinge"/>
                          <geom name="joint_tail_dyn" type="box" size="0.055 0.04498 0.045" density="220" rgba="0 0 0 0" contype="0" conaffinity="0" group="4"/>
                          <geom name="joint_tail_vis" type="mesh" mesh="tail_joint_mesh" mass="0" rgba="0.17 0.56 0.56 1" contype="0" conaffinity="0" group="1"/>
                          <site name="joint_tail_left" pos="-0.05 0.0375 0"/>
                          <site name="joint_tail_right" pos="-0.05 -0.0375 0"/>
                          <body name="tail_seg1" pos="-0.080785 0 0">
                            <joint name="tail_seg1_yaw" class="tail_hinge"/>
                            <geom name="tail_seg1_dyn" type="box" size="0.025785 0.0075 0.043364" density="140" rgba="0 0 0 0" contype="0" conaffinity="0" group="4"/>
                            <geom name="tail_seg1_vis" type="mesh" mesh="tail_seg1_mesh" mass="0" rgba="0.88 0.75 0.44 1" contype="0" conaffinity="0" group="1"/>
                            <body name="tail_seg2" pos="-0.055 0 0">
                              <joint name="tail_seg2_yaw" class="tail_hinge"/>
                              <geom name="tail_seg2_dyn" type="box" size="0.029215 0.006935 0.043302" density="140" rgba="0 0 0 0" contype="0" conaffinity="0" group="4"/>
                              <geom name="tail_seg2_vis" type="mesh" mesh="tail_seg2_mesh" mass="0" rgba="0.88 0.75 0.44 1" contype="0" conaffinity="0" group="1"/>
                              <body name="tail_seg3" pos="-0.059215 0 0">
                                <joint name="tail_seg3_yaw" class="tail_hinge"/>
                                <geom name="tail_seg3_dyn" type="box" size="0.03 0.005405 0.038704" density="140" rgba="0 0 0 0" contype="0" conaffinity="0" group="4"/>
                                <geom name="tail_seg3_vis" type="mesh" mesh="tail_seg3_mesh" mass="0" rgba="0.88 0.75 0.44 1" contype="0" conaffinity="0" group="1"/>
                                <body name="tail_seg4" pos="-0.06 0 0">
                                  <joint name="tail_seg4_yaw" class="tail_hinge"/>
                                  <geom name="tail_seg4_dyn" type="box" size="0.03 0.003834 0.033982" density="140" rgba="0 0 0 0" contype="0" conaffinity="0" group="4"/>
                                  <geom name="tail_seg4_vis" type="mesh" mesh="tail_seg4_mesh" mass="0" rgba="0.88 0.75 0.44 1" contype="0" conaffinity="0" group="1"/>
                                </body>
                              </body>
                            </body>
                          </body>
                        </body>
                      </body>
                    </body>
                  </body>
                </body>
              </body>
            </body>
          </body>
        </body>
      </body>
    </body>
  </worldbody>
</mujoco>
