<mujoco model="eel_2d_tendon">
  <!-- Topology follows model/prompt_model.md; scale cues are adapted from model/fish.STEP (CAD units are millimeters). -->
  <compiler angle="degree" autolimits="true" inertiafromgeom="true"/>
  <option timestep="0.002" gravity="0 0 0" integrator="implicitfast" cone="elliptic" iterations="100">
    <flag contact="disable"/>
  </option>
  <default>
    <geom type="capsule" contype="0" conaffinity="0" group="1"/>
    <site type="sphere" size="0.004" rgba="0.90 0.20 0.20 1" group="3"/>
    <default class="root_joint">
      <joint limited="false" stiffness="0" armature="0.01" damping="0.4"/>
    </default>
    <default class="active_hinge">
      <joint type="hinge" axis="0 0 1" limited="true" range="-15 15" stiffness="1.041" damping="0.05" armature="0.0005"/>
    </default>
    <default class="tail_hinge">
      <joint type="hinge" axis="0 0 1" limited="true" range="-25 25" stiffness="0.18" damping="0.02" armature="0.0002"/>
    </default>
    <default class="tendon_motor">
      <motor ctrllimited="true" ctrlrange="0 100" gear="1"/>
    </default>
  </default>
  <worldbody>
    <light name="light" directional="true" diffuse="0.8 0.8 0.8" pos="0 0 2.5"/>    <camera name="top" pos="0 0 2.2" xyaxes="1 0 0 0 1 0"/>
    <camera name="oblique" pos="-1.2 -1.6 0.9" xyaxes="0.8 -0.6 0 0.2 0.3 0.93"/>
    <body name="centre_compartment" pos="0 0 0">
      <joint name="root_x" class="root_joint" type="slide" axis="1 0 0"/>
      <joint name="root_y" class="root_joint" type="slide" axis="0 1 0"/>
      <joint name="root_yaw" class="root_joint" type="hinge" axis="0 0 1"/>
      <geom name="centre_compartment_geom" type="box" size="0.175 0.055 0.045" density="190" rgba="0.16 0.22 0.35 1"/>
      <site name="centre_reference" pos="0 0 0" rgba="0 0 0 0"/>
      <site name="centre_front_left" pos="0.175 0.0375 0"/>
      <site name="centre_front_right" pos="0.175 -0.0375 0"/>
      <site name="centre_back_left" pos="-0.175 0.0375 0"/>
      <site name="centre_back_right" pos="-0.175 -0.0375 0"/>
      <body name="front_v1" pos="0.19325 0 0">
        <joint name="front_v1_yaw" class="active_hinge" pos="-0.01825 0 0"/>
        <geom name="front_v1_geom" type="capsule" fromto="-0.01825 0 0 0.01825 0 0" size="0.028" density="220" rgba="0.18 0.48 0.78 1"/>
        <site name="front_v1_left" pos="0 0.0375 0"/>
        <site name="front_v1_right" pos="0 -0.0375 0"/>
        <body name="front_v2" pos="0.0365 0 0">
          <joint name="front_v2_yaw" class="active_hinge" pos="-0.01825 0 0"/>
          <geom name="front_v2_geom" type="capsule" fromto="-0.01825 0 0 0.01825 0 0" size="0.028" density="220" rgba="0.18 0.48 0.78 1"/>
          <site name="front_v2_left" pos="0 0.0375 0"/>
          <site name="front_v2_right" pos="0 -0.0375 0"/>
          <body name="front_v3" pos="0.0365 0 0">
            <joint name="front_v3_yaw" class="active_hinge" pos="-0.01825 0 0"/>
            <geom name="front_v3_geom" type="capsule" fromto="-0.01825 0 0 0.01825 0 0" size="0.028" density="220" rgba="0.18 0.48 0.78 1"/>
            <site name="front_v3_left" pos="0 0.0375 0"/>
            <site name="front_v3_right" pos="0 -0.0375 0"/>
            <body name="front_v4" pos="0.0365 0 0">
              <joint name="front_v4_yaw" class="active_hinge" pos="-0.01825 0 0"/>
              <geom name="front_v4_geom" type="capsule" fromto="-0.01825 0 0 0.01825 0 0" size="0.028" density="220" rgba="0.18 0.48 0.78 1"/>
              <site name="front_v4_left" pos="0 0.0375 0"/>
              <site name="front_v4_right" pos="0 -0.0375 0"/>
              <body name="front_v5" pos="0.0365 0 0">
                <joint name="front_v5_yaw" class="active_hinge" pos="-0.01825 0 0"/>
                <geom name="front_v5_geom" type="capsule" fromto="-0.01825 0 0 0.01825 0 0" size="0.028" density="220" rgba="0.18 0.48 0.78 1"/>
                <site name="front_v5_left" pos="0 0.0375 0"/>
                <site name="front_v5_right" pos="0 -0.0375 0"/>
                <body name="front_v6" pos="0.0365 0 0">
                  <joint name="front_v6_yaw" class="active_hinge" pos="-0.01825 0 0"/>
                  <geom name="front_v6_geom" type="capsule" fromto="-0.01825 0 0 0.01825 0 0" size="0.028" density="220" rgba="0.18 0.48 0.78 1"/>
                  <site name="front_v6_left" pos="0 0.0375 0"/>
                  <site name="front_v6_right" pos="0 -0.0375 0"/>
                  <body name="front_v7" pos="0.0365 0 0">
                    <joint name="front_v7_yaw" class="active_hinge" pos="-0.01825 0 0"/>
                    <geom name="front_v7_geom" type="capsule" fromto="-0.01825 0 0 0.01825 0 0" size="0.028" density="220" rgba="0.18 0.48 0.78 1"/>
                    <site name="front_v7_left" pos="0 0.0375 0"/>
                    <site name="front_v7_right" pos="0 -0.0375 0"/>
                    <body name="front_v8" pos="0.0365 0 0">
                      <joint name="front_v8_yaw" class="active_hinge" pos="-0.01825 0 0"/>
                      <geom name="front_v8_geom" type="capsule" fromto="-0.01825 0 0 0.01825 0 0" size="0.028" density="220" rgba="0.18 0.48 0.78 1"/>
                      <site name="front_v8_left" pos="0 0.0375 0"/>
                      <site name="front_v8_right" pos="0 -0.0375 0"/>
                      <body name="front_v9" pos="0.0365 0 0">
                        <joint name="front_v9_yaw" class="active_hinge" pos="-0.01825 0 0"/>
                        <geom name="front_v9_geom" type="capsule" fromto="-0.01825 0 0 0.01825 0 0" size="0.028" density="220" rgba="0.18 0.48 0.78 1"/>
                        <site name="front_v9_left" pos="0 0.0375 0"/>
                        <site name="front_v9_right" pos="0 -0.0375 0"/>
                        <body name="head" pos="0.04825 0 0">
                          <joint name="head_yaw" class="active_hinge" pos="-0.03 0 0"/>
                          <geom name="head_geom" type="capsule" fromto="-0.03 0 0 0.03 0 0" size="0.034" density="220" rgba="0.10 0.35 0.62 1"/>
                          <site name="head_left" pos="-0.018 0.0375 0"/>
                          <site name="head_right" pos="-0.018 -0.0375 0"/>
                        </body>
                      </body>
                    </body>
                  </body>
                </body>
              </body>
            </body>
          </body>
        </body>
      </body>
      <body name="back_v1" pos="-0.19325 0 0">
        <joint name="back_v1_yaw" class="active_hinge" pos="0.01825 0 0"/>
        <geom name="back_v1_geom" type="capsule" fromto="-0.01825 0 0 0.01825 0 0" size="0.026" density="220" rgba="0.22 0.62 0.62 1"/>
        <site name="back_v1_left" pos="0 0.0375 0"/>
        <site name="back_v1_right" pos="0 -0.0375 0"/>
        <body name="back_v2" pos="-0.0365 0 0">
          <joint name="back_v2_yaw" class="active_hinge" pos="0.01825 0 0"/>
          <geom name="back_v2_geom" type="capsule" fromto="-0.01825 0 0 0.01825 0 0" size="0.026" density="220" rgba="0.22 0.62 0.62 1"/>
          <site name="back_v2_left" pos="0 0.0375 0"/>
          <site name="back_v2_right" pos="0 -0.0375 0"/>
          <body name="back_v3" pos="-0.0365 0 0">
            <joint name="back_v3_yaw" class="active_hinge" pos="0.01825 0 0"/>
            <geom name="back_v3_geom" type="capsule" fromto="-0.01825 0 0 0.01825 0 0" size="0.026" density="220" rgba="0.22 0.62 0.62 1"/>
            <site name="back_v3_left" pos="0 0.0375 0"/>
            <site name="back_v3_right" pos="0 -0.0375 0"/>
            <body name="back_v4" pos="-0.0365 0 0">
              <joint name="back_v4_yaw" class="active_hinge" pos="0.01825 0 0"/>
              <geom name="back_v4_geom" type="capsule" fromto="-0.01825 0 0 0.01825 0 0" size="0.026" density="220" rgba="0.22 0.62 0.62 1"/>
              <site name="back_v4_left" pos="0 0.0375 0"/>
              <site name="back_v4_right" pos="0 -0.0375 0"/>
              <body name="back_v5" pos="-0.0365 0 0">
                <joint name="back_v5_yaw" class="active_hinge" pos="0.01825 0 0"/>
                <geom name="back_v5_geom" type="capsule" fromto="-0.01825 0 0 0.01825 0 0" size="0.026" density="220" rgba="0.22 0.62 0.62 1"/>
                <site name="back_v5_left" pos="0 0.0375 0"/>
                <site name="back_v5_right" pos="0 -0.0375 0"/>
                <body name="back_v6" pos="-0.0365 0 0">
                  <joint name="back_v6_yaw" class="active_hinge" pos="0.01825 0 0"/>
                  <geom name="back_v6_geom" type="capsule" fromto="-0.01825 0 0 0.01825 0 0" size="0.026" density="220" rgba="0.22 0.62 0.62 1"/>
                  <site name="back_v6_left" pos="0 0.0375 0"/>
                  <site name="back_v6_right" pos="0 -0.0375 0"/>
                  <body name="back_v7" pos="-0.0365 0 0">
                    <joint name="back_v7_yaw" class="active_hinge" pos="0.01825 0 0"/>
                    <geom name="back_v7_geom" type="capsule" fromto="-0.01825 0 0 0.01825 0 0" size="0.026" density="220" rgba="0.22 0.62 0.62 1"/>
                    <site name="back_v7_left" pos="0 0.0375 0"/>
                    <site name="back_v7_right" pos="0 -0.0375 0"/>
                    <body name="back_v8" pos="-0.0365 0 0">
                      <joint name="back_v8_yaw" class="active_hinge" pos="0.01825 0 0"/>
                      <geom name="back_v8_geom" type="capsule" fromto="-0.01825 0 0 0.01825 0 0" size="0.026" density="220" rgba="0.22 0.62 0.62 1"/>
                      <site name="back_v8_left" pos="0 0.0375 0"/>
                      <site name="back_v8_right" pos="0 -0.0375 0"/>
                      <body name="back_v9" pos="-0.0365 0 0">
                        <joint name="back_v9_yaw" class="active_hinge" pos="0.01825 0 0"/>
                        <geom name="back_v9_geom" type="capsule" fromto="-0.01825 0 0 0.01825 0 0" size="0.026" density="220" rgba="0.22 0.62 0.62 1"/>
                        <site name="back_v9_left" pos="0 0.0375 0"/>
                        <site name="back_v9_right" pos="0 -0.0375 0"/>
                        <body name="joint_tail" pos="-0.04075 0 0">
                          <joint name="joint_tail_yaw" class="active_hinge" pos="0.0225 0 0"/>
                          <geom name="joint_tail_geom" type="capsule" fromto="-0.0225 0 0 0.0225 0 0" size="0.022" density="220" rgba="0.17 0.53 0.53 1"/>
                          <site name="joint_tail_left" pos="0.015 0.0375 0"/>
                          <site name="joint_tail_right" pos="0.015 -0.0375 0"/>
                          <body name="tail_seg1" pos="-0.045 0 0">
                            <joint name="tail_seg1_yaw" class="tail_hinge" pos="0.0225 0 0"/>
                            <geom name="tail_seg1_geom" type="capsule" fromto="-0.0225 0 0 0.0225 0 0" size="0.018" density="140" rgba="0.88 0.74 0.42 1"/>
                            <body name="tail_seg2" pos="-0.0435 0 0">
                              <joint name="tail_seg2_yaw" class="tail_hinge" pos="0.021 0 0"/>
                              <geom name="tail_seg2_geom" type="capsule" fromto="-0.021 0 0 0.021 0 0" size="0.016" density="140" rgba="0.88 0.74 0.42 1"/>
                              <body name="tail_seg3" pos="-0.039 0 0">
                                <joint name="tail_seg3_yaw" class="tail_hinge" pos="0.018 0 0"/>
                                <geom name="tail_seg3_geom" type="capsule" fromto="-0.018 0 0 0.018 0 0" size="0.014" density="140" rgba="0.88 0.74 0.42 1"/>
                                <body name="tail_seg4" pos="-0.033 0 0">
                                  <joint name="tail_seg4_yaw" class="tail_hinge" pos="0.015 0 0"/>
                                  <geom name="tail_seg4_geom" type="capsule" fromto="-0.015 0 0 0.015 0 0" size="0.012" density="140" rgba="0.88 0.74 0.42 1"/>
                                </body>
                              </body>
                            </body>
                          </body>
                        </body>
                      </body>
                    </body>
                  </body>
                </body>
              </body>
            </body>
          </body>
        </body>
      </body>
    </body>
  </worldbody>
  <tendon>
    <spatial name="front_wire_left" width="0.0025" rgba="0.95 0.25 0.25 1">
      <site site="centre_front_left"/>
      <site site="front_v1_left"/>
      <site site="front_v2_left"/>
      <site site="front_v3_left"/>
      <site site="front_v4_left"/>
      <site site="front_v5_left"/>
      <site site="front_v6_left"/>
      <site site="front_v7_left"/>
      <site site="front_v8_left"/>
      <site site="front_v9_left"/>
      <site site="head_left"/>
    </spatial>
    <spatial name="front_wire_right" width="0.0025" rgba="0.85 0.18 0.18 1">
      <site site="centre_front_right"/>
      <site site="front_v1_right"/>
      <site site="front_v2_right"/>
      <site site="front_v3_right"/>
      <site site="front_v4_right"/>
      <site site="front_v5_right"/>
      <site site="front_v6_right"/>
      <site site="front_v7_right"/>
      <site site="front_v8_right"/>
      <site site="front_v9_right"/>
      <site site="head_right"/>
    </spatial>
    <spatial name="back_wire_left" width="0.0025" rgba="0.25 0.80 0.80 1">
      <site site="centre_back_left"/>
      <site site="back_v1_left"/>
      <site site="back_v2_left"/>
      <site site="back_v3_left"/>
      <site site="back_v4_left"/>
      <site site="back_v5_left"/>
      <site site="back_v6_left"/>
      <site site="back_v7_left"/>
      <site site="back_v8_left"/>
      <site site="back_v9_left"/>
      <site site="joint_tail_left"/>
    </spatial>
    <spatial name="back_wire_right" width="0.0025" rgba="0.18 0.68 0.68 1">
      <site site="centre_back_right"/>
      <site site="back_v1_right"/>
      <site site="back_v2_right"/>
      <site site="back_v3_right"/>
      <site site="back_v4_right"/>
      <site site="back_v5_right"/>
      <site site="back_v6_right"/>
      <site site="back_v7_right"/>
      <site site="back_v8_right"/>
      <site site="back_v9_right"/>
      <site site="joint_tail_right"/>
    </spatial>
  </tendon>
  <actuator>
    <motor name="front_left_motor" class="tendon_motor" tendon="front_wire_left"/>
    <motor name="front_right_motor" class="tendon_motor" tendon="front_wire_right"/>
    <motor name="back_left_motor" class="tendon_motor" tendon="back_wire_left"/>
    <motor name="back_right_motor" class="tendon_motor" tendon="back_wire_right"/>
  </actuator>
  <sensor>
    <jointpos name="root_x_pos_sensor" joint="root_x"/>
    <jointpos name="root_y_pos_sensor" joint="root_y"/>
    <jointpos name="root_yaw_pos_sensor" joint="root_yaw"/>
    <jointvel name="root_x_vel_sensor" joint="root_x"/>
    <jointvel name="root_y_vel_sensor" joint="root_y"/>
    <jointvel name="root_yaw_vel_sensor" joint="root_yaw"/>
    <framepos name="head_pos" objtype="xbody" objname="head"/>
    <framepos name="joint_tail_pos" objtype="xbody" objname="joint_tail"/>
    <framexaxis name="centre_xaxis" objtype="xbody" objname="centre_compartment"/>
  </sensor>
</mujoco>
